ERROR 2023-12-12 16:43:19,589 log Internal Server Error: /admin/auth/user/add/
Traceback (most recent call last):
  File "F:\apps-ads\apps-ads\env\Lib\site-packages\django\db\backends\utils.py", line 105, in _execute
    return self.cursor.execute(sql, params)
           ^^^^^^^^^^^^^^^^^^^^^^^^^^^^^^^^
psycopg2.errors.UndefinedTable: relation "users_user" does not exist
LINE 1: ...user"."date_joined", "users_user"."platform" FROM "users_use...
                                                             ^


The above exception was the direct cause of the following exception:

Traceback (most recent call last):
  File "F:\apps-ads\apps-ads\env\Lib\site-packages\django\core\handlers\exception.py", line 55, in inner
    response = get_response(request)
               ^^^^^^^^^^^^^^^^^^^^^
  File "F:\apps-ads\apps-ads\env\Lib\site-packages\django\core\handlers\base.py", line 197, in _get_response
    response = wrapped_callback(request, *callback_args, **callback_kwargs)
               ^^^^^^^^^^^^^^^^^^^^^^^^^^^^^^^^^^^^^^^^^^^^^^^^^^^^^^^^^^^^
  File "F:\apps-ads\apps-ads\env\Lib\site-packages\django\contrib\admin\sites.py", line 259, in wrapper
    return self.admin_view(view, cacheable)(*args, **kwargs)
           ^^^^^^^^^^^^^^^^^^^^^^^^^^^^^^^^^^^^^^^^^^^^^^^^^
  File "F:\apps-ads\apps-ads\env\Lib\site-packages\django\utils\decorators.py", line 188, in _view_wrapper
    result = _process_exception(request, e)
             ^^^^^^^^^^^^^^^^^^^^^^^^^^^^^^
  File "F:\apps-ads\apps-ads\env\Lib\site-packages\django\utils\decorators.py", line 186, in _view_wrapper
    response = view_func(request, *args, **kwargs)
               ^^^^^^^^^^^^^^^^^^^^^^^^^^^^^^^^^^^
  File "F:\apps-ads\apps-ads\env\Lib\site-packages\django\views\decorators\cache.py", line 80, in _view_wrapper
    response = view_func(request, *args, **kwargs)
               ^^^^^^^^^^^^^^^^^^^^^^^^^^^^^^^^^^^
  File "F:\apps-ads\apps-ads\env\Lib\site-packages\django\contrib\admin\sites.py", line 228, in inner
    if not self.has_permission(request):
           ^^^^^^^^^^^^^^^^^^^^^^^^^^^^
  File "F:\apps-ads\apps-ads\env\Lib\site-packages\django\contrib\admin\sites.py", line 201, in has_permission
    return request.user.is_active and request.user.is_staff
           ^^^^^^^^^^^^^^^^^^^^^^
  File "F:\apps-ads\apps-ads\env\Lib\site-packages\django\utils\functional.py", line 251, in inner
    self._setup()
  File "F:\apps-ads\apps-ads\env\Lib\site-packages\django\utils\functional.py", line 404, in _setup
    self._wrapped = self._setupfunc()
                    ^^^^^^^^^^^^^^^^^
  File "F:\apps-ads\apps-ads\env\Lib\site-packages\django\contrib\auth\middleware.py", line 33, in <lambda>
    request.user = SimpleLazyObject(lambda: get_user(request))
                                            ^^^^^^^^^^^^^^^^^
  File "F:\apps-ads\apps-ads\env\Lib\site-packages\django\contrib\auth\middleware.py", line 13, in get_user
    request._cached_user = auth.get_user(request)
                           ^^^^^^^^^^^^^^^^^^^^^^
  File "F:\apps-ads\apps-ads\env\Lib\site-packages\django\contrib\auth\__init__.py", line 216, in get_user
    user = backend.get_user(user_id)
           ^^^^^^^^^^^^^^^^^^^^^^^^^
  File "F:\apps-ads\apps-ads\env\Lib\site-packages\django\contrib\auth\backends.py", line 157, in get_user
    user = UserModel._default_manager.get(pk=user_id)
           ^^^^^^^^^^^^^^^^^^^^^^^^^^^^^^^^^^^^^^^^^^
  File "F:\apps-ads\apps-ads\env\Lib\site-packages\django\db\models\manager.py", line 87, in manager_method
    return getattr(self.get_queryset(), name)(*args, **kwargs)
           ^^^^^^^^^^^^^^^^^^^^^^^^^^^^^^^^^^^^^^^^^^^^^^^^^^^
  File "F:\apps-ads\apps-ads\env\Lib\site-packages\django\db\models\query.py", line 643, in get
    num = len(clone)
          ^^^^^^^^^^
  File "F:\apps-ads\apps-ads\env\Lib\site-packages\django\db\models\query.py", line 380, in __len__
    self._fetch_all()
  File "F:\apps-ads\apps-ads\env\Lib\site-packages\django\db\models\query.py", line 1926, in _fetch_all
    self._result_cache = list(self._iterable_class(self))
                         ^^^^^^^^^^^^^^^^^^^^^^^^^^^^^^^^
  File "F:\apps-ads\apps-ads\env\Lib\site-packages\django\db\models\query.py", line 91, in __iter__
    results = compiler.execute_sql(
              ^^^^^^^^^^^^^^^^^^^^^
  File "F:\apps-ads\apps-ads\env\Lib\site-packages\django\db\models\sql\compiler.py", line 1562, in execute_sql
    cursor.execute(sql, params)
  File "F:\apps-ads\apps-ads\env\Lib\site-packages\django\db\backends\utils.py", line 122, in execute
    return super().execute(sql, params)
           ^^^^^^^^^^^^^^^^^^^^^^^^^^^^
  File "F:\apps-ads\apps-ads\env\Lib\site-packages\django\db\backends\utils.py", line 79, in execute
    return self._execute_with_wrappers(
           ^^^^^^^^^^^^^^^^^^^^^^^^^^^^
  File "F:\apps-ads\apps-ads\env\Lib\site-packages\django\db\backends\utils.py", line 92, in _execute_with_wrappers
    return executor(sql, params, many, context)
           ^^^^^^^^^^^^^^^^^^^^^^^^^^^^^^^^^^^^
  File "F:\apps-ads\apps-ads\env\Lib\site-packages\django\db\backends\utils.py", line 100, in _execute
    with self.db.wrap_database_errors:
  File "F:\apps-ads\apps-ads\env\Lib\site-packages\django\db\utils.py", line 91, in __exit__
    raise dj_exc_value.with_traceback(traceback) from exc_value
  File "F:\apps-ads\apps-ads\env\Lib\site-packages\django\db\backends\utils.py", line 105, in _execute
    return self.cursor.execute(sql, params)
           ^^^^^^^^^^^^^^^^^^^^^^^^^^^^^^^^
django.db.utils.ProgrammingError: relation "users_user" does not exist
LINE 1: ...user"."date_joined", "users_user"."platform" FROM "users_use...
                                                             ^

ERROR 2023-12-12 16:43:19,595 basehttp "POST /admin/auth/user/add/ HTTP/1.1" 500 186105
ERROR 2023-12-12 16:43:27,864 log Internal Server Error: /admin/
Traceback (most recent call last):
  File "F:\apps-ads\apps-ads\env\Lib\site-packages\django\db\backends\utils.py", line 105, in _execute
    return self.cursor.execute(sql, params)
           ^^^^^^^^^^^^^^^^^^^^^^^^^^^^^^^^
psycopg2.errors.UndefinedTable: relation "users_user" does not exist
LINE 1: ...user"."date_joined", "users_user"."platform" FROM "users_use...
                                                             ^


The above exception was the direct cause of the following exception:

Traceback (most recent call last):
  File "F:\apps-ads\apps-ads\env\Lib\site-packages\django\core\handlers\exception.py", line 55, in inner
    response = get_response(request)
               ^^^^^^^^^^^^^^^^^^^^^
  File "F:\apps-ads\apps-ads\env\Lib\site-packages\django\core\handlers\base.py", line 197, in _get_response
    response = wrapped_callback(request, *callback_args, **callback_kwargs)
               ^^^^^^^^^^^^^^^^^^^^^^^^^^^^^^^^^^^^^^^^^^^^^^^^^^^^^^^^^^^^
  File "F:\apps-ads\apps-ads\env\Lib\site-packages\django\contrib\admin\sites.py", line 259, in wrapper
    return self.admin_view(view, cacheable)(*args, **kwargs)
           ^^^^^^^^^^^^^^^^^^^^^^^^^^^^^^^^^^^^^^^^^^^^^^^^^
  File "F:\apps-ads\apps-ads\env\Lib\site-packages\django\utils\decorators.py", line 188, in _view_wrapper
    result = _process_exception(request, e)
             ^^^^^^^^^^^^^^^^^^^^^^^^^^^^^^
  File "F:\apps-ads\apps-ads\env\Lib\site-packages\django\utils\decorators.py", line 186, in _view_wrapper
    response = view_func(request, *args, **kwargs)
               ^^^^^^^^^^^^^^^^^^^^^^^^^^^^^^^^^^^
  File "F:\apps-ads\apps-ads\env\Lib\site-packages\django\views\decorators\cache.py", line 80, in _view_wrapper
    response = view_func(request, *args, **kwargs)
               ^^^^^^^^^^^^^^^^^^^^^^^^^^^^^^^^^^^
  File "F:\apps-ads\apps-ads\env\Lib\site-packages\django\contrib\admin\sites.py", line 228, in inner
    if not self.has_permission(request):
           ^^^^^^^^^^^^^^^^^^^^^^^^^^^^
  File "F:\apps-ads\apps-ads\env\Lib\site-packages\django\contrib\admin\sites.py", line 201, in has_permission
    return request.user.is_active and request.user.is_staff
           ^^^^^^^^^^^^^^^^^^^^^^
  File "F:\apps-ads\apps-ads\env\Lib\site-packages\django\utils\functional.py", line 251, in inner
    self._setup()
  File "F:\apps-ads\apps-ads\env\Lib\site-packages\django\utils\functional.py", line 404, in _setup
    self._wrapped = self._setupfunc()
                    ^^^^^^^^^^^^^^^^^
  File "F:\apps-ads\apps-ads\env\Lib\site-packages\django\contrib\auth\middleware.py", line 33, in <lambda>
    request.user = SimpleLazyObject(lambda: get_user(request))
                                            ^^^^^^^^^^^^^^^^^
  File "F:\apps-ads\apps-ads\env\Lib\site-packages\django\contrib\auth\middleware.py", line 13, in get_user
    request._cached_user = auth.get_user(request)
                           ^^^^^^^^^^^^^^^^^^^^^^
  File "F:\apps-ads\apps-ads\env\Lib\site-packages\django\contrib\auth\__init__.py", line 216, in get_user
    user = backend.get_user(user_id)
           ^^^^^^^^^^^^^^^^^^^^^^^^^
  File "F:\apps-ads\apps-ads\env\Lib\site-packages\django\contrib\auth\backends.py", line 157, in get_user
    user = UserModel._default_manager.get(pk=user_id)
           ^^^^^^^^^^^^^^^^^^^^^^^^^^^^^^^^^^^^^^^^^^
  File "F:\apps-ads\apps-ads\env\Lib\site-packages\django\db\models\manager.py", line 87, in manager_method
    return getattr(self.get_queryset(), name)(*args, **kwargs)
           ^^^^^^^^^^^^^^^^^^^^^^^^^^^^^^^^^^^^^^^^^^^^^^^^^^^
  File "F:\apps-ads\apps-ads\env\Lib\site-packages\django\db\models\query.py", line 643, in get
    num = len(clone)
          ^^^^^^^^^^
  File "F:\apps-ads\apps-ads\env\Lib\site-packages\django\db\models\query.py", line 380, in __len__
    self._fetch_all()
  File "F:\apps-ads\apps-ads\env\Lib\site-packages\django\db\models\query.py", line 1926, in _fetch_all
    self._result_cache = list(self._iterable_class(self))
                         ^^^^^^^^^^^^^^^^^^^^^^^^^^^^^^^^
  File "F:\apps-ads\apps-ads\env\Lib\site-packages\django\db\models\query.py", line 91, in __iter__
    results = compiler.execute_sql(
              ^^^^^^^^^^^^^^^^^^^^^
  File "F:\apps-ads\apps-ads\env\Lib\site-packages\django\db\models\sql\compiler.py", line 1562, in execute_sql
    cursor.execute(sql, params)
  File "F:\apps-ads\apps-ads\env\Lib\site-packages\django\db\backends\utils.py", line 122, in execute
    return super().execute(sql, params)
           ^^^^^^^^^^^^^^^^^^^^^^^^^^^^
  File "F:\apps-ads\apps-ads\env\Lib\site-packages\django\db\backends\utils.py", line 79, in execute
    return self._execute_with_wrappers(
           ^^^^^^^^^^^^^^^^^^^^^^^^^^^^
  File "F:\apps-ads\apps-ads\env\Lib\site-packages\django\db\backends\utils.py", line 92, in _execute_with_wrappers
    return executor(sql, params, many, context)
           ^^^^^^^^^^^^^^^^^^^^^^^^^^^^^^^^^^^^
  File "F:\apps-ads\apps-ads\env\Lib\site-packages\django\db\backends\utils.py", line 100, in _execute
    with self.db.wrap_database_errors:
  File "F:\apps-ads\apps-ads\env\Lib\site-packages\django\db\utils.py", line 91, in __exit__
    raise dj_exc_value.with_traceback(traceback) from exc_value
  File "F:\apps-ads\apps-ads\env\Lib\site-packages\django\db\backends\utils.py", line 105, in _execute
    return self.cursor.execute(sql, params)
           ^^^^^^^^^^^^^^^^^^^^^^^^^^^^^^^^
django.db.utils.ProgrammingError: relation "users_user" does not exist
LINE 1: ...user"."date_joined", "users_user"."platform" FROM "users_use...
                                                             ^

ERROR 2023-12-12 16:43:27,867 basehttp "GET /admin/ HTTP/1.1" 500 182971
ERROR 2023-12-12 16:43:28,351 log Internal Server Error: /admin/
Traceback (most recent call last):
  File "F:\apps-ads\apps-ads\env\Lib\site-packages\django\db\backends\utils.py", line 105, in _execute
    return self.cursor.execute(sql, params)
           ^^^^^^^^^^^^^^^^^^^^^^^^^^^^^^^^
psycopg2.errors.UndefinedTable: relation "users_user" does not exist
LINE 1: ...user"."date_joined", "users_user"."platform" FROM "users_use...
                                                             ^


The above exception was the direct cause of the following exception:

Traceback (most recent call last):
  File "F:\apps-ads\apps-ads\env\Lib\site-packages\django\core\handlers\exception.py", line 55, in inner
    response = get_response(request)
               ^^^^^^^^^^^^^^^^^^^^^
  File "F:\apps-ads\apps-ads\env\Lib\site-packages\django\core\handlers\base.py", line 197, in _get_response
    response = wrapped_callback(request, *callback_args, **callback_kwargs)
               ^^^^^^^^^^^^^^^^^^^^^^^^^^^^^^^^^^^^^^^^^^^^^^^^^^^^^^^^^^^^
  File "F:\apps-ads\apps-ads\env\Lib\site-packages\django\contrib\admin\sites.py", line 259, in wrapper
    return self.admin_view(view, cacheable)(*args, **kwargs)
           ^^^^^^^^^^^^^^^^^^^^^^^^^^^^^^^^^^^^^^^^^^^^^^^^^
  File "F:\apps-ads\apps-ads\env\Lib\site-packages\django\utils\decorators.py", line 188, in _view_wrapper
    result = _process_exception(request, e)
             ^^^^^^^^^^^^^^^^^^^^^^^^^^^^^^
  File "F:\apps-ads\apps-ads\env\Lib\site-packages\django\utils\decorators.py", line 186, in _view_wrapper
    response = view_func(request, *args, **kwargs)
               ^^^^^^^^^^^^^^^^^^^^^^^^^^^^^^^^^^^
  File "F:\apps-ads\apps-ads\env\Lib\site-packages\django\views\decorators\cache.py", line 80, in _view_wrapper
    response = view_func(request, *args, **kwargs)
               ^^^^^^^^^^^^^^^^^^^^^^^^^^^^^^^^^^^
  File "F:\apps-ads\apps-ads\env\Lib\site-packages\django\contrib\admin\sites.py", line 228, in inner
    if not self.has_permission(request):
           ^^^^^^^^^^^^^^^^^^^^^^^^^^^^
  File "F:\apps-ads\apps-ads\env\Lib\site-packages\django\contrib\admin\sites.py", line 201, in has_permission
    return request.user.is_active and request.user.is_staff
           ^^^^^^^^^^^^^^^^^^^^^^
  File "F:\apps-ads\apps-ads\env\Lib\site-packages\django\utils\functional.py", line 251, in inner
    self._setup()
  File "F:\apps-ads\apps-ads\env\Lib\site-packages\django\utils\functional.py", line 404, in _setup
    self._wrapped = self._setupfunc()
                    ^^^^^^^^^^^^^^^^^
  File "F:\apps-ads\apps-ads\env\Lib\site-packages\django\contrib\auth\middleware.py", line 33, in <lambda>
    request.user = SimpleLazyObject(lambda: get_user(request))
                                            ^^^^^^^^^^^^^^^^^
  File "F:\apps-ads\apps-ads\env\Lib\site-packages\django\contrib\auth\middleware.py", line 13, in get_user
    request._cached_user = auth.get_user(request)
                           ^^^^^^^^^^^^^^^^^^^^^^
  File "F:\apps-ads\apps-ads\env\Lib\site-packages\django\contrib\auth\__init__.py", line 216, in get_user
    user = backend.get_user(user_id)
           ^^^^^^^^^^^^^^^^^^^^^^^^^
  File "F:\apps-ads\apps-ads\env\Lib\site-packages\django\contrib\auth\backends.py", line 157, in get_user
    user = UserModel._default_manager.get(pk=user_id)
           ^^^^^^^^^^^^^^^^^^^^^^^^^^^^^^^^^^^^^^^^^^
  File "F:\apps-ads\apps-ads\env\Lib\site-packages\django\db\models\manager.py", line 87, in manager_method
    return getattr(self.get_queryset(), name)(*args, **kwargs)
           ^^^^^^^^^^^^^^^^^^^^^^^^^^^^^^^^^^^^^^^^^^^^^^^^^^^
  File "F:\apps-ads\apps-ads\env\Lib\site-packages\django\db\models\query.py", line 643, in get
    num = len(clone)
          ^^^^^^^^^^
  File "F:\apps-ads\apps-ads\env\Lib\site-packages\django\db\models\query.py", line 380, in __len__
    self._fetch_all()
  File "F:\apps-ads\apps-ads\env\Lib\site-packages\django\db\models\query.py", line 1926, in _fetch_all
    self._result_cache = list(self._iterable_class(self))
                         ^^^^^^^^^^^^^^^^^^^^^^^^^^^^^^^^
  File "F:\apps-ads\apps-ads\env\Lib\site-packages\django\db\models\query.py", line 91, in __iter__
    results = compiler.execute_sql(
              ^^^^^^^^^^^^^^^^^^^^^
  File "F:\apps-ads\apps-ads\env\Lib\site-packages\django\db\models\sql\compiler.py", line 1562, in execute_sql
    cursor.execute(sql, params)
  File "F:\apps-ads\apps-ads\env\Lib\site-packages\django\db\backends\utils.py", line 122, in execute
    return super().execute(sql, params)
           ^^^^^^^^^^^^^^^^^^^^^^^^^^^^
  File "F:\apps-ads\apps-ads\env\Lib\site-packages\django\db\backends\utils.py", line 79, in execute
    return self._execute_with_wrappers(
           ^^^^^^^^^^^^^^^^^^^^^^^^^^^^
  File "F:\apps-ads\apps-ads\env\Lib\site-packages\django\db\backends\utils.py", line 92, in _execute_with_wrappers
    return executor(sql, params, many, context)
           ^^^^^^^^^^^^^^^^^^^^^^^^^^^^^^^^^^^^
  File "F:\apps-ads\apps-ads\env\Lib\site-packages\django\db\backends\utils.py", line 100, in _execute
    with self.db.wrap_database_errors:
  File "F:\apps-ads\apps-ads\env\Lib\site-packages\django\db\utils.py", line 91, in __exit__
    raise dj_exc_value.with_traceback(traceback) from exc_value
  File "F:\apps-ads\apps-ads\env\Lib\site-packages\django\db\backends\utils.py", line 105, in _execute
    return self.cursor.execute(sql, params)
           ^^^^^^^^^^^^^^^^^^^^^^^^^^^^^^^^
django.db.utils.ProgrammingError: relation "users_user" does not exist
LINE 1: ...user"."date_joined", "users_user"."platform" FROM "users_use...
                                                             ^

ERROR 2023-12-12 16:43:28,355 basehttp "GET /admin/ HTTP/1.1" 500 182697
ERROR 2023-12-12 16:56:58,250 log Internal Server Error: /admin/
Traceback (most recent call last):
  File "F:\apps-ads\apps-ads\env\Lib\site-packages\django\db\backends\utils.py", line 105, in _execute
    return self.cursor.execute(sql, params)
           ^^^^^^^^^^^^^^^^^^^^^^^^^^^^^^^^
psycopg2.errors.UndefinedTable: relation "users_user" does not exist
LINE 1: ...user"."date_joined", "users_user"."platform" FROM "users_use...
                                                             ^


The above exception was the direct cause of the following exception:

Traceback (most recent call last):
  File "F:\apps-ads\apps-ads\env\Lib\site-packages\django\core\handlers\exception.py", line 55, in inner
    response = get_response(request)
               ^^^^^^^^^^^^^^^^^^^^^
  File "F:\apps-ads\apps-ads\env\Lib\site-packages\django\core\handlers\base.py", line 197, in _get_response
    response = wrapped_callback(request, *callback_args, **callback_kwargs)
               ^^^^^^^^^^^^^^^^^^^^^^^^^^^^^^^^^^^^^^^^^^^^^^^^^^^^^^^^^^^^
  File "F:\apps-ads\apps-ads\env\Lib\site-packages\django\contrib\admin\sites.py", line 259, in wrapper
    return self.admin_view(view, cacheable)(*args, **kwargs)
           ^^^^^^^^^^^^^^^^^^^^^^^^^^^^^^^^^^^^^^^^^^^^^^^^^
  File "F:\apps-ads\apps-ads\env\Lib\site-packages\django\utils\decorators.py", line 188, in _view_wrapper
    result = _process_exception(request, e)
             ^^^^^^^^^^^^^^^^^^^^^^^^^^^^^^
  File "F:\apps-ads\apps-ads\env\Lib\site-packages\django\utils\decorators.py", line 186, in _view_wrapper
    response = view_func(request, *args, **kwargs)
               ^^^^^^^^^^^^^^^^^^^^^^^^^^^^^^^^^^^
  File "F:\apps-ads\apps-ads\env\Lib\site-packages\django\views\decorators\cache.py", line 80, in _view_wrapper
    response = view_func(request, *args, **kwargs)
               ^^^^^^^^^^^^^^^^^^^^^^^^^^^^^^^^^^^
  File "F:\apps-ads\apps-ads\env\Lib\site-packages\django\contrib\admin\sites.py", line 228, in inner
    if not self.has_permission(request):
           ^^^^^^^^^^^^^^^^^^^^^^^^^^^^
  File "F:\apps-ads\apps-ads\env\Lib\site-packages\django\contrib\admin\sites.py", line 201, in has_permission
    return request.user.is_active and request.user.is_staff
           ^^^^^^^^^^^^^^^^^^^^^^
  File "F:\apps-ads\apps-ads\env\Lib\site-packages\django\utils\functional.py", line 251, in inner
    self._setup()
  File "F:\apps-ads\apps-ads\env\Lib\site-packages\django\utils\functional.py", line 404, in _setup
    self._wrapped = self._setupfunc()
                    ^^^^^^^^^^^^^^^^^
  File "F:\apps-ads\apps-ads\env\Lib\site-packages\django\contrib\auth\middleware.py", line 33, in <lambda>
    request.user = SimpleLazyObject(lambda: get_user(request))
                                            ^^^^^^^^^^^^^^^^^
  File "F:\apps-ads\apps-ads\env\Lib\site-packages\django\contrib\auth\middleware.py", line 13, in get_user
    request._cached_user = auth.get_user(request)
                           ^^^^^^^^^^^^^^^^^^^^^^
  File "F:\apps-ads\apps-ads\env\Lib\site-packages\django\contrib\auth\__init__.py", line 216, in get_user
    user = backend.get_user(user_id)
           ^^^^^^^^^^^^^^^^^^^^^^^^^
  File "F:\apps-ads\apps-ads\env\Lib\site-packages\django\contrib\auth\backends.py", line 157, in get_user
    user = UserModel._default_manager.get(pk=user_id)
           ^^^^^^^^^^^^^^^^^^^^^^^^^^^^^^^^^^^^^^^^^^
  File "F:\apps-ads\apps-ads\env\Lib\site-packages\django\db\models\manager.py", line 87, in manager_method
    return getattr(self.get_queryset(), name)(*args, **kwargs)
           ^^^^^^^^^^^^^^^^^^^^^^^^^^^^^^^^^^^^^^^^^^^^^^^^^^^
  File "F:\apps-ads\apps-ads\env\Lib\site-packages\django\db\models\query.py", line 643, in get
    num = len(clone)
          ^^^^^^^^^^
  File "F:\apps-ads\apps-ads\env\Lib\site-packages\django\db\models\query.py", line 380, in __len__
    self._fetch_all()
  File "F:\apps-ads\apps-ads\env\Lib\site-packages\django\db\models\query.py", line 1926, in _fetch_all
    self._result_cache = list(self._iterable_class(self))
                         ^^^^^^^^^^^^^^^^^^^^^^^^^^^^^^^^
  File "F:\apps-ads\apps-ads\env\Lib\site-packages\django\db\models\query.py", line 91, in __iter__
    results = compiler.execute_sql(
              ^^^^^^^^^^^^^^^^^^^^^
  File "F:\apps-ads\apps-ads\env\Lib\site-packages\django\db\models\sql\compiler.py", line 1562, in execute_sql
    cursor.execute(sql, params)
  File "F:\apps-ads\apps-ads\env\Lib\site-packages\django\db\backends\utils.py", line 122, in execute
    return super().execute(sql, params)
           ^^^^^^^^^^^^^^^^^^^^^^^^^^^^
  File "F:\apps-ads\apps-ads\env\Lib\site-packages\django\db\backends\utils.py", line 79, in execute
    return self._execute_with_wrappers(
           ^^^^^^^^^^^^^^^^^^^^^^^^^^^^
  File "F:\apps-ads\apps-ads\env\Lib\site-packages\django\db\backends\utils.py", line 92, in _execute_with_wrappers
    return executor(sql, params, many, context)
           ^^^^^^^^^^^^^^^^^^^^^^^^^^^^^^^^^^^^
  File "F:\apps-ads\apps-ads\env\Lib\site-packages\django\db\backends\utils.py", line 100, in _execute
    with self.db.wrap_database_errors:
  File "F:\apps-ads\apps-ads\env\Lib\site-packages\django\db\utils.py", line 91, in __exit__
    raise dj_exc_value.with_traceback(traceback) from exc_value
  File "F:\apps-ads\apps-ads\env\Lib\site-packages\django\db\backends\utils.py", line 105, in _execute
    return self.cursor.execute(sql, params)
           ^^^^^^^^^^^^^^^^^^^^^^^^^^^^^^^^
django.db.utils.ProgrammingError: relation "users_user" does not exist
LINE 1: ...user"."date_joined", "users_user"."platform" FROM "users_use...
                                                             ^

ERROR 2023-12-12 16:56:58,254 basehttp "GET /admin/ HTTP/1.1" 500 182834
ERROR 2023-12-12 16:59:05,953 log Internal Server Error: /admin/
Traceback (most recent call last):
  File "F:\apps-ads\apps-ads\env\Lib\site-packages\django\db\backends\utils.py", line 105, in _execute
    return self.cursor.execute(sql, params)
           ^^^^^^^^^^^^^^^^^^^^^^^^^^^^^^^^
psycopg2.errors.UndefinedTable: relation "users_user" does not exist
LINE 1: ...user"."date_joined", "users_user"."platform" FROM "users_use...
                                                             ^


The above exception was the direct cause of the following exception:

Traceback (most recent call last):
  File "F:\apps-ads\apps-ads\env\Lib\site-packages\django\core\handlers\exception.py", line 55, in inner
    response = get_response(request)
               ^^^^^^^^^^^^^^^^^^^^^
  File "F:\apps-ads\apps-ads\env\Lib\site-packages\django\core\handlers\base.py", line 197, in _get_response
    response = wrapped_callback(request, *callback_args, **callback_kwargs)
               ^^^^^^^^^^^^^^^^^^^^^^^^^^^^^^^^^^^^^^^^^^^^^^^^^^^^^^^^^^^^
  File "F:\apps-ads\apps-ads\env\Lib\site-packages\django\contrib\admin\sites.py", line 259, in wrapper
    return self.admin_view(view, cacheable)(*args, **kwargs)
           ^^^^^^^^^^^^^^^^^^^^^^^^^^^^^^^^^^^^^^^^^^^^^^^^^
  File "F:\apps-ads\apps-ads\env\Lib\site-packages\django\utils\decorators.py", line 188, in _view_wrapper
    result = _process_exception(request, e)
             ^^^^^^^^^^^^^^^^^^^^^^^^^^^^^^
  File "F:\apps-ads\apps-ads\env\Lib\site-packages\django\utils\decorators.py", line 186, in _view_wrapper
    response = view_func(request, *args, **kwargs)
               ^^^^^^^^^^^^^^^^^^^^^^^^^^^^^^^^^^^
  File "F:\apps-ads\apps-ads\env\Lib\site-packages\django\views\decorators\cache.py", line 80, in _view_wrapper
    response = view_func(request, *args, **kwargs)
               ^^^^^^^^^^^^^^^^^^^^^^^^^^^^^^^^^^^
  File "F:\apps-ads\apps-ads\env\Lib\site-packages\django\contrib\admin\sites.py", line 228, in inner
    if not self.has_permission(request):
           ^^^^^^^^^^^^^^^^^^^^^^^^^^^^
  File "F:\apps-ads\apps-ads\env\Lib\site-packages\django\contrib\admin\sites.py", line 201, in has_permission
    return request.user.is_active and request.user.is_staff
           ^^^^^^^^^^^^^^^^^^^^^^
  File "F:\apps-ads\apps-ads\env\Lib\site-packages\django\utils\functional.py", line 251, in inner
    self._setup()
  File "F:\apps-ads\apps-ads\env\Lib\site-packages\django\utils\functional.py", line 404, in _setup
    self._wrapped = self._setupfunc()
                    ^^^^^^^^^^^^^^^^^
  File "F:\apps-ads\apps-ads\env\Lib\site-packages\django\contrib\auth\middleware.py", line 33, in <lambda>
    request.user = SimpleLazyObject(lambda: get_user(request))
                                            ^^^^^^^^^^^^^^^^^
  File "F:\apps-ads\apps-ads\env\Lib\site-packages\django\contrib\auth\middleware.py", line 13, in get_user
    request._cached_user = auth.get_user(request)
                           ^^^^^^^^^^^^^^^^^^^^^^
  File "F:\apps-ads\apps-ads\env\Lib\site-packages\django\contrib\auth\__init__.py", line 216, in get_user
    user = backend.get_user(user_id)
           ^^^^^^^^^^^^^^^^^^^^^^^^^
  File "F:\apps-ads\apps-ads\env\Lib\site-packages\django\contrib\auth\backends.py", line 157, in get_user
    user = UserModel._default_manager.get(pk=user_id)
           ^^^^^^^^^^^^^^^^^^^^^^^^^^^^^^^^^^^^^^^^^^
  File "F:\apps-ads\apps-ads\env\Lib\site-packages\django\db\models\manager.py", line 87, in manager_method
    return getattr(self.get_queryset(), name)(*args, **kwargs)
           ^^^^^^^^^^^^^^^^^^^^^^^^^^^^^^^^^^^^^^^^^^^^^^^^^^^
  File "F:\apps-ads\apps-ads\env\Lib\site-packages\django\db\models\query.py", line 643, in get
    num = len(clone)
          ^^^^^^^^^^
  File "F:\apps-ads\apps-ads\env\Lib\site-packages\django\db\models\query.py", line 380, in __len__
    self._fetch_all()
  File "F:\apps-ads\apps-ads\env\Lib\site-packages\django\db\models\query.py", line 1926, in _fetch_all
    self._result_cache = list(self._iterable_class(self))
                         ^^^^^^^^^^^^^^^^^^^^^^^^^^^^^^^^
  File "F:\apps-ads\apps-ads\env\Lib\site-packages\django\db\models\query.py", line 91, in __iter__
    results = compiler.execute_sql(
              ^^^^^^^^^^^^^^^^^^^^^
  File "F:\apps-ads\apps-ads\env\Lib\site-packages\django\db\models\sql\compiler.py", line 1562, in execute_sql
    cursor.execute(sql, params)
  File "F:\apps-ads\apps-ads\env\Lib\site-packages\django\db\backends\utils.py", line 122, in execute
    return super().execute(sql, params)
           ^^^^^^^^^^^^^^^^^^^^^^^^^^^^
  File "F:\apps-ads\apps-ads\env\Lib\site-packages\django\db\backends\utils.py", line 79, in execute
    return self._execute_with_wrappers(
           ^^^^^^^^^^^^^^^^^^^^^^^^^^^^
  File "F:\apps-ads\apps-ads\env\Lib\site-packages\django\db\backends\utils.py", line 92, in _execute_with_wrappers
    return executor(sql, params, many, context)
           ^^^^^^^^^^^^^^^^^^^^^^^^^^^^^^^^^^^^
  File "F:\apps-ads\apps-ads\env\Lib\site-packages\django\db\backends\utils.py", line 100, in _execute
    with self.db.wrap_database_errors:
  File "F:\apps-ads\apps-ads\env\Lib\site-packages\django\db\utils.py", line 91, in __exit__
    raise dj_exc_value.with_traceback(traceback) from exc_value
  File "F:\apps-ads\apps-ads\env\Lib\site-packages\django\db\backends\utils.py", line 105, in _execute
    return self.cursor.execute(sql, params)
           ^^^^^^^^^^^^^^^^^^^^^^^^^^^^^^^^
django.db.utils.ProgrammingError: relation "users_user" does not exist
LINE 1: ...user"."date_joined", "users_user"."platform" FROM "users_use...
                                                             ^

ERROR 2023-12-12 16:59:05,962 basehttp "GET /admin/ HTTP/1.1" 500 182834
ERROR 2023-12-12 17:05:17,098 log Internal Server Error: /admin/
Traceback (most recent call last):
  File "F:\apps-ads\apps-ads\env\Lib\site-packages\django\db\backends\utils.py", line 105, in _execute
    return self.cursor.execute(sql, params)
           ^^^^^^^^^^^^^^^^^^^^^^^^^^^^^^^^
psycopg2.errors.UndefinedTable: relation "users_user" does not exist
LINE 1: ...user"."date_joined", "users_user"."platform" FROM "users_use...
                                                             ^


The above exception was the direct cause of the following exception:

Traceback (most recent call last):
  File "F:\apps-ads\apps-ads\env\Lib\site-packages\django\core\handlers\exception.py", line 55, in inner
    response = get_response(request)
               ^^^^^^^^^^^^^^^^^^^^^
  File "F:\apps-ads\apps-ads\env\Lib\site-packages\django\core\handlers\base.py", line 197, in _get_response
    response = wrapped_callback(request, *callback_args, **callback_kwargs)
               ^^^^^^^^^^^^^^^^^^^^^^^^^^^^^^^^^^^^^^^^^^^^^^^^^^^^^^^^^^^^
  File "F:\apps-ads\apps-ads\env\Lib\site-packages\django\contrib\admin\sites.py", line 259, in wrapper
    return self.admin_view(view, cacheable)(*args, **kwargs)
           ^^^^^^^^^^^^^^^^^^^^^^^^^^^^^^^^^^^^^^^^^^^^^^^^^
  File "F:\apps-ads\apps-ads\env\Lib\site-packages\django\utils\decorators.py", line 188, in _view_wrapper
    result = _process_exception(request, e)
             ^^^^^^^^^^^^^^^^^^^^^^^^^^^^^^
  File "F:\apps-ads\apps-ads\env\Lib\site-packages\django\utils\decorators.py", line 186, in _view_wrapper
    response = view_func(request, *args, **kwargs)
               ^^^^^^^^^^^^^^^^^^^^^^^^^^^^^^^^^^^
  File "F:\apps-ads\apps-ads\env\Lib\site-packages\django\views\decorators\cache.py", line 80, in _view_wrapper
    response = view_func(request, *args, **kwargs)
               ^^^^^^^^^^^^^^^^^^^^^^^^^^^^^^^^^^^
  File "F:\apps-ads\apps-ads\env\Lib\site-packages\django\contrib\admin\sites.py", line 228, in inner
    if not self.has_permission(request):
           ^^^^^^^^^^^^^^^^^^^^^^^^^^^^
  File "F:\apps-ads\apps-ads\env\Lib\site-packages\django\contrib\admin\sites.py", line 201, in has_permission
    return request.user.is_active and request.user.is_staff
           ^^^^^^^^^^^^^^^^^^^^^^
  File "F:\apps-ads\apps-ads\env\Lib\site-packages\django\utils\functional.py", line 251, in inner
    self._setup()
  File "F:\apps-ads\apps-ads\env\Lib\site-packages\django\utils\functional.py", line 404, in _setup
    self._wrapped = self._setupfunc()
                    ^^^^^^^^^^^^^^^^^
  File "F:\apps-ads\apps-ads\env\Lib\site-packages\django\contrib\auth\middleware.py", line 33, in <lambda>
    request.user = SimpleLazyObject(lambda: get_user(request))
                                            ^^^^^^^^^^^^^^^^^
  File "F:\apps-ads\apps-ads\env\Lib\site-packages\django\contrib\auth\middleware.py", line 13, in get_user
    request._cached_user = auth.get_user(request)
                           ^^^^^^^^^^^^^^^^^^^^^^
  File "F:\apps-ads\apps-ads\env\Lib\site-packages\django\contrib\auth\__init__.py", line 216, in get_user
    user = backend.get_user(user_id)
           ^^^^^^^^^^^^^^^^^^^^^^^^^
  File "F:\apps-ads\apps-ads\env\Lib\site-packages\django\contrib\auth\backends.py", line 157, in get_user
    user = UserModel._default_manager.get(pk=user_id)
           ^^^^^^^^^^^^^^^^^^^^^^^^^^^^^^^^^^^^^^^^^^
  File "F:\apps-ads\apps-ads\env\Lib\site-packages\django\db\models\manager.py", line 87, in manager_method
    return getattr(self.get_queryset(), name)(*args, **kwargs)
           ^^^^^^^^^^^^^^^^^^^^^^^^^^^^^^^^^^^^^^^^^^^^^^^^^^^
  File "F:\apps-ads\apps-ads\env\Lib\site-packages\django\db\models\query.py", line 643, in get
    num = len(clone)
          ^^^^^^^^^^
  File "F:\apps-ads\apps-ads\env\Lib\site-packages\django\db\models\query.py", line 380, in __len__
    self._fetch_all()
  File "F:\apps-ads\apps-ads\env\Lib\site-packages\django\db\models\query.py", line 1926, in _fetch_all
    self._result_cache = list(self._iterable_class(self))
                         ^^^^^^^^^^^^^^^^^^^^^^^^^^^^^^^^
  File "F:\apps-ads\apps-ads\env\Lib\site-packages\django\db\models\query.py", line 91, in __iter__
    results = compiler.execute_sql(
              ^^^^^^^^^^^^^^^^^^^^^
  File "F:\apps-ads\apps-ads\env\Lib\site-packages\django\db\models\sql\compiler.py", line 1562, in execute_sql
    cursor.execute(sql, params)
  File "F:\apps-ads\apps-ads\env\Lib\site-packages\django\db\backends\utils.py", line 122, in execute
    return super().execute(sql, params)
           ^^^^^^^^^^^^^^^^^^^^^^^^^^^^
  File "F:\apps-ads\apps-ads\env\Lib\site-packages\django\db\backends\utils.py", line 79, in execute
    return self._execute_with_wrappers(
           ^^^^^^^^^^^^^^^^^^^^^^^^^^^^
  File "F:\apps-ads\apps-ads\env\Lib\site-packages\django\db\backends\utils.py", line 92, in _execute_with_wrappers
    return executor(sql, params, many, context)
           ^^^^^^^^^^^^^^^^^^^^^^^^^^^^^^^^^^^^
  File "F:\apps-ads\apps-ads\env\Lib\site-packages\django\db\backends\utils.py", line 100, in _execute
    with self.db.wrap_database_errors:
  File "F:\apps-ads\apps-ads\env\Lib\site-packages\django\db\utils.py", line 91, in __exit__
    raise dj_exc_value.with_traceback(traceback) from exc_value
  File "F:\apps-ads\apps-ads\env\Lib\site-packages\django\db\backends\utils.py", line 105, in _execute
    return self.cursor.execute(sql, params)
           ^^^^^^^^^^^^^^^^^^^^^^^^^^^^^^^^
django.db.utils.ProgrammingError: relation "users_user" does not exist
LINE 1: ...user"."date_joined", "users_user"."platform" FROM "users_use...
                                                             ^

ERROR 2023-12-12 17:05:17,102 basehttp "GET /admin/ HTTP/1.1" 500 182834
